Workbook

Sheet 说明
A1: 销售数据分析仪表盘
A2: 数据年度：2025 年 | 维度：产品线 × 区域 × 销售员 × 客户 | 生成方式：公式驱动
A4: 工作表 | B4: 内容
A5: 销售明细 | B5: 1200 行事实表：月份 / 产品线 / 区域 / 销售员 / 客户 / 销售额 / 成本（毛利与毛利率由公式计出）
A6: 月度趋势 | B6: 12 个月汇总：销售额、成本、毛利、毛利率、上年同期、环比增长、同比增长（均为公式）
A7: 区域业绩排名 | B7: 按区域汇总销售额与毛利，并用 RANK 公式排出名次
A8: 产品线毛利分析 | B8: 按产品线汇总销售额、成本、毛利、毛利率（公式）
A9: 客户汇总 | B9: 40 家客户汇总，供 Top10 引用
A10: Top10客户 | B10: 用 LARGE + INDEX/MATCH 公式取贡献最高的 10 家客户及累计占比
A11: KPI仪表盘 | B11: 年销售额 / 年毛利 / 平均毛利率目标与达成率，含数据条条件格式
A13: 使用提示 | B13: 所有汇总与比率均为 Excel 实时公式，修改「销售明细」后会自动重算；图表随数据联动。
A14: 说明 | B14: 示例数据为确定性随机生成，仅用于演示仪表盘结构，请替换为真实业务数据。

Sheet 销售明细
A1: 月份 | B1: 产品线 | C1: 区域 | D1: 销售员 | E1: 客户 | F1: 销售额 | G1: 成本
A2: 2025-01 | B2: 篮球装备 | C2: 华东 | D2: 张伟 | E2: 启航健身中心 | F2: 90000 | G2: 59200 | H2: 30800 | I2: 0.34222222
A3: 2025-01 | B3: 篮球装备 | C3: 华东 | D3: 李娜 | E3: 篮途体育文化 | F3: 97200 | G3: 61900 | H3: 35300 | I3: 0.36316872
A4: 2025-01 | B4: 篮球装备 | C4: 华东 | D4: 王芳 | E4: 跃动少儿运动馆 | F4: 90700 | G4: 60200 | H4: 30500 | I4: 0.33627343
A5: 2025-01 | B5: 篮球装备 | C5: 华东 | D5: 刘强 | E5: 成长树运动馆 | F5: 67600 | G5: 42200 | H5: 25400 | I5: 0.37573964
A6: 2025-01 | B6: 篮球装备 | C6: 华东 | D6: 陈静 | E6: 健将体育 | F6: 76800 | G6: 50300 | H6: 26500 | I6: 0.34505208
A7: 2025-01 | B7: 篮球装备 | C7: 华北 | D7: 张伟 | E7: 飞跃训练营 | F7: 62100 | G7: 41800 | H7: 20300 | I7: 0.32689211
A8: 2025-01 | B8: 篮球装备 | C8: 华北 | D8: 李娜 | E8: 巅峰运动 | F8: 62700 | G8: 40500 | H8: 22200 | I8: 0.35406699
A9: 2025-01 | B9: 篮球装备 | C9: 华北 | D9: 王芳 | E9: 星跃体育 | F9: 71700 | G9: 44700 | H9: 27000 | I9: 0.37656904
A10: 2025-01 | B10: 篮球装备 | C10: 华北 | D10: 刘强 | E10: 小飞侠运动俱乐部 | F10: 56600 | G10: 35600 | H10: 21000 | I10: 0.37102473
A11: 2025-01 | B11: 篮球装备 | C11: 华北 | D11: 陈静 | E11: 小小运动家 | F11: 62500 | G11: 41100 | H11: 21400 | I11: 0.3424
A12: 2025-01 | B12: 篮球装备 | C12: 华南 | D12: 张伟 | E12: 成长树运动馆 | F12: 70800 | G12: 44600 | H12: 26200 | I12: 0.3700565
A13: 2025-01 | B13: 篮球装备 | C13: 华南 | D13: 李娜 | E13: 元气营养 | F13: 62200 | G13: 40900 | H13: 21300 | I13: 0.34244373
... A1201: 2025-12 | B1201: 智能穿戴 | C1201: 西部 | D1201: 陈静 | E1201: 领跑体育 | F1201: 73800 | G1201: 46900 | H1201: 26900 | I1201: 0.36449864

Sheet 月度趋势
A1: 月度销售趋势与增长率
A3: 月份 | B3: 销售额 | C3: 成本 | D3: 毛利 | E3: 毛利率 | F3: 上年同期销售额 | G3: 环比增长 | H3: 同比增长
A4: 2025-01 | B4: =SUMIFS('销售明细'!F2:F1201,'销售明细'!A2:A1201,A4) | C4: =SUMIFS('销售明细'!G2:G1201,'销售明细'!A2:A1201,A4) | D4: =B4-C4 | E4: =IF(B4=0,"",D4/B4) | F4: 3705700 | H4: =IF(F4=0,"",(B4-F4)/F4)
A5: 2025-02 | B5: =SUMIFS('销售明细'!F2:F1201,'销售明细'!A2:A1201,A5) | C5: =SUMIFS('销售明细'!G2:G1201,'销售明细'!A2:A1201,A5) | D5: =B5-C5 | E5: =IF(B5=0,"",D5/B5) | F5: 3791600 | G5: =IF(B4=0,"",(B5-B4)/B4) | H5: =IF(F5=0,"",(B5-F5)/F5)
A6: 2025-03 | B6: =SUMIFS('销售明细'!F2:F1201,'销售明细'!A2:A1201,A6) | C6: =SUMIFS('销售明细'!G2:G1201,'销售明细'!A2:A1201,A6) | D6: =B6-C6 | E6: =IF(B6=0,"",D6/B6) | F6: 4553300 | G6: =IF(B5=0,"",(B6-B5)/B5) | H6: =IF(F6=0,"",(B6-F6)/F6)
A7: 2025-04 | B7: =SUMIFS('销售明细'!F2:F1201,'销售明细'!A2:A1201,A7) | C7: =SUMIFS('销售明细'!G2:G1201,'销售明细'!A2:A1201,A7) | D7: =B7-C7 | E7: =IF(B7=0,"",D7/B7) | F7: 4729500 | G7: =IF(B6=0,"",(B7-B6)/B6) | H7: =IF(F7=0,"",(B7-F7)/F7)
A8: 2025-05 | B8: =SUMIFS('销售明细'!F2:F1201,'销售明细'!A2:A1201,A8) | C8: =SUMIFS('销售明细'!G2:G1201,'销售明细'!A2:A1201,A8) | D8: =B8-C8 | E8: =IF(B8=0,"",D8/B8) | F8: 4872400 | G8: =IF(B7=0,"",(B8-B7)/B7) | H8: =IF(F8=0,"",(B8-F8)/F8)
A9: 2025-06 | B9: =SUMIFS('销售明细'!F2:F1201,'销售明细'!A2:A1201,A9) | C9: =SUMIFS('销售明细'!G2:G1201,'销售明细'!A2:A1201,A9) | D9: =B9-C9 | E9: =IF(B9=0,"",D9/B9) | F9: 6075900 | G9: =IF(B8=0,"",(B9-B8)/B8) | H9: =IF(F9=0,"",(B9-F9)/F9)
A10: 2025-07 | B10: =SUMIFS('销售明细'!F2:F1201,'销售明细'!A2:A1201,A10) | C10: =SUMIFS('销售明细'!G2:G1201,'销售明细'!A2:A1201,A10) | D10: =B10-C10 | E10: =IF(B10=0,"",D10/B10) | F10: 4170200 | G10: =IF(B9=0,"",(B10-B9)/B9) | H10: =IF(F10=0,"",(B10-F10)/F10)
A11: 2025-08 | B11: =SUMIFS('销售明细'!F2:F1201,'销售明细'!A2:A1201,A11) | C11: =SUMIFS('销售明细'!G2:G1201,'销售明细'!A2:A1201,A11) | D11: =B11-C11 | E11: =IF(B11=0,"",D11/B11) | F11: 4405700 | G11: =IF(B10=0,"",(B11-B10)/B10) | H11: =IF(F11=0,"",(B11-F11)/F11)
A12: 2025-09 | B12: =SUMIFS('销售明细'!F2:F1201,'销售明细'!A2:A1201,A12) | C12: =SUMIFS('销售明细'!G2:G1201,'销售明细'!A2:A1201,A12) | D12: =B12-C12 | E12: =IF(B12=0,"",D12/B12) | F12: 5096200 | G12: =IF(B11=0,"",(B12-B11)/B11) | H12: =IF(F12=0,"",(B12-F12)/F12)
A13: 2025-10 | B13: =SUMIFS('销售明细'!F2:F1201,'销售明细'!A2:A1201,A13) | C13: =SUMIFS('销售明细'!G2:G1201,'销售明细'!A2:A1201,A13) | D13: =B13-C13 | E13: =IF(B13=0,"",D13/B13) | F13: 5303800 | G13: =IF(B12=0,"",(B13-B12)/B12) | H13: =IF(F13=0,"",(B13-F13)/F13)
A14: 2025-11 | B14: =SUMIFS('销售明细'!F2:F1201,'销售明细'!A2:A1201,A14) | C14: =SUMIFS('销售明细'!G2:G1201,'销售明细'!A2:A1201,A14) | D14: =B14-C14 | E14: =IF(B14=0,"",D14/B14) | F14: 6018800 | G14: =IF(B13=0,"",(B14-B13)/B13) | H14: =IF(F14=0,"",(B14-F14)/F14)
A15: 2025-12 | B15: =SUMIFS('销售明细'!F2:F1201,'销售明细'!A2:A1201,A15) | C15: =SUMIFS('销售明细'!G2:G1201,'销售明细'!A2:A1201,A15) | D15: =B15-C15 | E15: =IF(B15=0,"",D15/B15) | F15: 6917500 | G15: =IF(B14=0,"",(B15-B14)/B14) | H15: =IF(F15=0,"",(B15-F15)/F15)

Sheet 区域业绩排名
A1: 区域业绩排名
A3: 区域 | B3: 销售额 | C3: 成本 | D3: 毛利 | E3: 毛利率 | F3: 排名
A4: 华东 | B4: =SUMIFS('销售明细'!F2:F1201,'销售明细'!C2:C1201,A4) | C4: =SUMIFS('销售明细'!G2:G1201,'销售明细'!C2:C1201,A4) | D4: =B4-C4 | E4: =IF(B4=0,"",D4/B4) | F4: =RANK(B4,$B$4:$B$7)
A5: 华北 | B5: =SUMIFS('销售明细'!F2:F1201,'销售明细'!C2:C1201,A5) | C5: =SUMIFS('销售明细'!G2:G1201,'销售明细'!C2:C1201,A5) | D5: =B5-C5 | E5: =IF(B5=0,"",D5/B5) | F5: =RANK(B5,$B$4:$B$7)
A6: 华南 | B6: =SUMIFS('销售明细'!F2:F1201,'销售明细'!C2:C1201,A6) | C6: =SUMIFS('销售明细'!G2:G1201,'销售明细'!C2:C1201,A6) | D6: =B6-C6 | E6: =IF(B6=0,"",D6/B6) | F6: =RANK(B6,$B$4:$B$7)
A7: 西部 | B7: =SUMIFS('销售明细'!F2:F1201,'销售明细'!C2:C1201,A7) | C7: =SUMIFS('销售明细'!G2:G1201,'销售明细'!C2:C1201,A7) | D7: =B7-C7 | E7: =IF(B7=0,"",D7/B7) | F7: =RANK(B7,$B$4:$B$7)

Sheet 产品线毛利分析
A1: 产品线毛利分析
A3: 产品线 | B3: 销售额 | C3: 成本 | D3: 毛利 | E3: 毛利率
A4: 篮球装备 | B4: =SUMIFS('销售明细'!F2:F1201,'销售明细'!B2:B1201,A4) | C4: =SUMIFS('销售明细'!G2:G1201,'销售明细'!B2:B1201,A4) | D4: =B4-C4 | E4: =IF(B4=0,"",D4/B4)
A5: 体适能器材 | B5: =SUMIFS('销售明细'!F2:F1201,'销售明细'!B2:B1201,A5) | C5: =SUMIFS('销售明细'!G2:G1201,'销售明细'!B2:B1201,A5) | D5: =B5-C5 | E5: =IF(B5=0,"",D5/B5)
A6: 训练服饰 | B6: =SUMIFS('销售明细'!F2:F1201,'销售明细'!B2:B1201,A6) | C6: =SUMIFS('销售明细'!G2:G1201,'销售明细'!B2:B1201,A6) | D6: =B6-C6 | E6: =IF(B6=0,"",D6/B6)
A7: 营养补给 | B7: =SUMIFS('销售明细'!F2:F1201,'销售明细'!B2:B1201,A7) | C7: =SUMIFS('销售明细'!G2:G1201,'销售明细'!B2:B1201,A7) | D7: =B7-C7 | E7: =IF(B7=0,"",D7/B7)
A8: 智能穿戴 | B8: =SUMIFS('销售明细'!F2:F1201,'销售明细'!B2:B1201,A8) | C8: =SUMIFS('销售明细'!G2:G1201,'销售明细'!B2:B1201,A8) | D8: =B8-C8 | E8: =IF(B8=0,"",D8/B8)

Sheet 客户汇总
A1: 客户汇总（按销售额）
A3: 客户 | B3: 销售额 | C3: 成本 | D3: 毛利 | E3: 毛利率
A4: 锐动体育用品 | B4: =SUMIFS('销售明细'!F2:F1201,'销售明细'!E2:E1201,A4) | C4: =SUMIFS('销售明细'!G2:G1201,'销售明细'!E2:E1201,A4) | D4: =B4-C4 | E4: =IF(B4=0,"",D4/B4)
A5: 启航健身中心 | B5: =SUMIFS('销售明细'!F2:F1201,'销售明细'!E2:E1201,A5) | C5: =SUMIFS('销售明细'!G2:G1201,'销售明细'!E2:E1201,A5) | D5: =B5-C5 | E5: =IF(B5=0,"",D5/B5)
A6: 跃动少儿运动馆 | B6: =SUMIFS('销售明细'!F2:F1201,'销售明细'!E2:E1201,A6) | C6: =SUMIFS('销售明细'!G2:G1201,'销售明细'!E2:E1201,A6) | D6: =B6-C6 | E6: =IF(B6=0,"",D6/B6)
A7: 恒康营养 | B7: =SUMIFS('销售明细'!F2:F1201,'销售明细'!E2:E1201,A7) | C7: =SUMIFS('销售明细'!G2:G1201,'销售明细'!E2:E1201,A7) | D7: =B7-C7 | E7: =IF(B7=0,"",D7/B7)
A8: 锋行体育 | B8: =SUMIFS('销售明细'!F2:F1201,'销售明细'!E2:E1201,A8) | C8: =SUMIFS('销售明细'!G2:G1201,'销售明细'!E2:E1201,A8) | D8: =B8-C8 | E8: =IF(B8=0,"",D8/B8)
A9: 小飞侠运动俱乐部 | B9: =SUMIFS('销售明细'!F2:F1201,'销售明细'!E2:E1201,A9) | C9: =SUMIFS('销售明细'!G2:G1201,'销售明细'!E2:E1201,A9) | D9: =B9-C9 | E9: =IF(B9=0,"",D9/B9)
A10: 卓越体能训练营 | B10: =SUMIFS('销售明细'!F2:F1201,'销售明细'!E2:E1201,A10) | C10: =SUMIFS('销售明细'!G2:G1201,'销售明细'!E2:E1201,A10) | D10: =B10-C10 | E10: =IF(B10=0,"",D10/B10)
A11: 康威运动商城 | B11: =SUMIFS('销售明细'!F2:F1201,'销售明细'!E2:E1201,A11) | C11: =SUMIFS('销售明细'!G2:G1201,'销售明细'!E2:E1201,A11) | D11: =B11-C11 | E11: =IF(B11=0,"",D11/B11)
A12: 星跃体育 | B12: =SUMIFS('销售明细'!F2:F1201,'销售明细'!E2:E1201,A12) | C12: =SUMIFS('销售明细'!G2:G1201,'销售明细'!E2:E1201,A12) | D12: =B12-C12 | E12: =IF(B12=0,"",D12/B12)
A13: 活力无限健身 | B13: =SUMIFS('销售明细'!F2:F1201,'销售明细'!E2:E1201,A13) | C13: =SUMIFS('销售明细'!G2:G1201,'销售明细'!E2:E1201,A13) | D13: =B13-C13 | E13: =IF(B13=0,"",D13/B13)
A14: 篮途体育文化 | B14: =SUMIFS('销售明细'!F2:F1201,'销售明细'!E2:E1201,A14) | C14: =SUMIFS('销售明细'!G2:G1201,'销售明细'!E2:E1201,A14) | D14: =B14-C14 | E14: =IF(B14=0,"",D14/B14)
A15: 优加体能中心 | B15: =SUMIFS('销售明细'!F2:F1201,'销售明细'!E2:E1201,A15) | C15: =SUMIFS('销售明细'!G2:G1201,'销售明细'!E2:E1201,A15) | D15: =B15-C15 | E15: =IF(B15=0,"",D15/B15)
A16: 健将体育 | B16: =SUMIFS('销售明细'!F2:F1201,'销售明细'!E2:E1201,A16) | C16: =SUMIFS('销售明细'!G2:G1201,'销售明细'!E2:E1201,A16) | D16: =B16-C16 | E16: =IF(B16=0,"",D16/B16)
A17: 童行运动馆 | B17: =SUMIFS('销售明细'!F2:F1201,'销售明细'!E2:E1201,A17) | C17: =SUMIFS('销售明细'!G2:G1201,'销售明细'!E2:E1201,A17) | D17: =B17-C17 | E17: =IF(B17=0,"",D17/B17)
A18: 劲爆运动用品 | B18: =SUMIFS('销售明细'!F2:F1201,'销售明细'!E2:E1201,A18) | C18: =SUMIFS('销售明细'!G2:G1201,'销售明细'!E2:E1201,A18) | D18: =B18-C18 | E18: =IF(B18=0,"",D18/B18)
A19: 领跑体育 | B19: =SUMIFS('销售明细'!F2:F1201,'销售明细'!E2:E1201,A19) | C19: =SUMIFS('销售明细'!G2:G1201,'销售明细'!E2:E1201,A19) | D19: =B19-C19 | E19: =IF(B19=0,"",D19/B19)
A20: 天天向上健身 | B20: =SUMIFS('销售明细'!F2:F1201,'销售明细'!E2:E1201,A20) | C20: =SUMIFS('销售明细'!G2:G1201,'销售明细'!E2:E1201,A20) | D20: =B20-C20 | E20: =IF(B20=0,"",D20/B20)
A21: 冠军之路俱乐部 | B21: =SUMIFS('销售明细'!F2:F1201,'销售明细'!E2:E1201,A21) | C21: =SUMIFS('销售明细'!G2:G1201,'销售明细'!E2:E1201,A21) | D21: =B21-C21 | E21: =IF(B21=0,"",D21/B21)
A22: 迈步体育 | B22: =SUMIFS('销售明细'!F2:F1201,'销售明细'!E2:E1201,A22) | C22: =SUMIFS('销售明细'!G2:G1201,'销售明细'!E2:E1201,A22) | D22: =B22-C22 | E22: =IF(B22=0,"",D22/B22)
A23: 飞跃训练营 | B23: =SUMIFS('销售明细'!F2:F1201,'销售明细'!E2:E1201,A23) | C23: =SUMIFS('销售明细'!G2:G1201,'销售明细'!E2:E1201,A23) | D23: =B23-C23 | E23: =IF(B23=0,"",D23/B23)
A24: 动能营养 | B24: =SUMIFS('销售明细'!F2:F1201,'销售明细'!E2:E1201,A24) | C24: =SUMIFS('销售明细'!G2:G1201,'销售明细'!E2:E1201,A24) | D24: =B24-C24 | E24: =IF(B24=0,"",D24/B24)
A25: 风云篮球馆 | B25: =SUMIFS('销售明细'!F2:F1201,'销售明细'!E2:E1201,A25) | C25: =SUMIFS('销售明细'!G2:G1201,'销售明细'!E2:E1201,A25) | D25: =B25-C25 | E25: =IF(B25=0,"",D25/B25)
A26: 小小运动家 | B26: =SUMIFS('销售明细'!F2:F1201,'销售明细'!E2:E1201,A26) | C26: =SUMIFS('销售明细'!G2:G1201,'销售明细'!E2:E1201,A26) | D26: =B26-C26 | E26: =IF(B26=0,"",D26/B26)
A27: 强体体育 | B27: =SUMIFS('销售明细'!F2:F1201,'销售明细'!E2:E1201,A27) | C27: =SUMIFS('销售明细'!G2:G1201,'销售明细'!E2:E1201,A27) | D27: =B27-C27 | E27: =IF(B27=0,"",D27/B27)
A28: 锐健身工作室 | B28: =SUMIFS('销售明细'!F2:F1201,'销售明细'!E2:E1201,A28) | C28: =SUMIFS('销售明细'!G2:G1201,'销售明细'!E2:E1201,A28) | D28: =B28-C28 | E28: =IF(B28=0,"",D28/B28)
A29: 环宇体育 | B29: =SUMIFS('销售明细'!F2:F1201,'销售明细'!E2:E1201,A29) | C29: =SUMIFS('销售明细'!G2:G1201,'销售明细'!E2:E1201,A29) | D29: =B29-C29 | E29: =IF(B29=0,"",D29/B29)
A30: 茁长少儿体适能 | B30: =SUMIFS('销售明细'!F2:F1201,'销售明细'!E2:E1201,A30) | C30: =SUMIFS('销售明细'!G2:G1201,'销售明细'!E2:E1201,A30) | D30: =B30-C30 | E30: =IF(B30=0,"",D30/B30)
A31: 巅峰运动 | B31: =SUMIFS('销售明细'!F2:F1201,'销售明细'!E2:E1201,A31) | C31: =SUMIFS('销售明细'!G2:G1201,'销售明细'!E2:E1201,A31) | D31: =B31-C31 | E31: =IF(B31=0,"",D31/B31)
A32: 乐动体育 | B32: =SUMIFS('销售明细'!F2:F1201,'销售明细'!E2:E1201,A32) | C32: =SUMIFS('销售明细'!G2:G1201,'销售明细'!E2:E1201,A32) | D32: =B32-C32 | E32: =IF(B32=0,"",D32/B32)
A33: 极客穿戴 | B33: =SUMIFS('销售明细'!F2:F1201,'销售明细'!E2:E1201,A33) | C33: =SUMIFS('销售明细'!G2:G1201,'销售明细'!E2:E1201,A33) | D33: =B33-C33 | E33: =IF(B33=0,"",D33/B33)
A34: 腾飞体育用品 | B34: =SUMIFS('销售明细'!F2:F1201,'销售明细'!E2:E1201,A34) | C34: =SUMIFS('销售明细'!G2:G1201,'销售明细'!E2:E1201,A34) | D34: =B34-C34 | E34: =IF(B34=0,"",D34/B34)
A35: 阳光体能 | B35: =SUMIFS('销售明细'!F2:F1201,'销售明细'!E2:E1201,A35) | C35: =SUMIFS('销售明细'!G2:G1201,'销售明细'!E2:E1201,A35) | D35: =B35-C35 | E35: =IF(B35=0,"",D35/B35)
A36: 悍将运动 | B36: =SUMIFS('销售明细'!F2:F1201,'销售明细'!E2:E1201,A36) | C36: =SUMIFS('销售明细'!G2:G1201,'销售明细'!E2:E1201,A36) | D36: =B36-C36 | E36: =IF(B36=0,"",D36/B36)
A37: 智练体育 | B37: =SUMIFS('销售明细'!F2:F1201,'销售明细'!E2:E1201,A37) | C37: =SUMIFS('销售明细'!G2:G1201,'销售明细'!E2:E1201,A37) | D37: =B37-C37 | E37: =IF(B37=0,"",D37/B37)
A38: 元气营养 | B38: =SUMIFS('销售明细'!F2:F1201,'销售明细'!E2:E1201,A38) | C38: =SUMIFS('销售明细'!G2:G1201,'销售明细'!E2:E1201,A38) | D38: =B38-C38 | E38: =IF(B38=0,"",D38/B38)
A39: 雷霆篮球 | B39: =SUMIFS('销售明细'!F2:F1201,'销售明细'!E2:E1201,A39) | C39: =SUMIFS('销售明细'!G2:G1201,'销售明细'!E2:E1201,A39) | D39: =B39-C39 | E39: =IF(B39=0,"",D39/B39)
A40: 成长树运动馆 | B40: =SUMIFS('销售明细'!F2:F1201,'销售明细'!E2:E1201,A40) | C40: =SUMIFS('销售明细'!G2:G1201,'销售明细'!E2:E1201,A40) | D40: =B40-C40 | E40: =IF(B40=0,"",D40/B40)
A41: 超能体育 | B41: =SUMIFS('销售明细'!F2:F1201,'销售明细'!E2:E1201,A41) | C41: =SUMIFS('销售明细'!G2:G1201,'销售明细'!E2:E1201,A41) | D41: =B41-C41 | E41: =IF(B41=0,"",D41/B41)
...

Sheet Top10客户
A1: Top 10 客户贡献
A3: 排名 | B3: 客户 | C3: 销售额 | D3: 毛利 | E3: 贡献占比 | F3: 累计占比
A4: 1 | B4: =INDEX('客户汇总'!A4:A43,MATCH(LARGE('客户汇总'!B4:B43,A4),'客户汇总'!B4:B43,0)) | C4: =LARGE('客户汇总'!B4:B43,A4) | D4: =INDEX('客户汇总'!D4:D43,MATCH(B4,'客户汇总'!A4:A43,0)) | E4: =C4/SUM('客户汇总'!B4:B43) | F4: =E4
A5: 2 | B5: =INDEX('客户汇总'!A4:A43,MATCH(LARGE('客户汇总'!B4:B43,A5),'客户汇总'!B4:B43,0)) | C5: =LARGE('客户汇总'!B4:B43,A5) | D5: =INDEX('客户汇总'!D4:D43,MATCH(B5,'客户汇总'!A4:A43,0)) | E5: =C5/SUM('客户汇总'!B4:B43) | F5: =F4+E5
A6: 3 | B6: =INDEX('客户汇总'!A4:A43,MATCH(LARGE('客户汇总'!B4:B43,A6),'客户汇总'!B4:B43,0)) | C6: =LARGE('客户汇总'!B4:B43,A6) | D6: =INDEX('客户汇总'!D4:D43,MATCH(B6,'客户汇总'!A4:A43,0)) | E6: =C6/SUM('客户汇总'!B4:B43) | F6: =F5+E6
A7: 4 | B7: =INDEX('客户汇总'!A4:A43,MATCH(LARGE('客户汇总'!B4:B43,A7),'客户汇总'!B4:B43,0)) | C7: =LARGE('客户汇总'!B4:B43,A7) | D7: =INDEX('客户汇总'!D4:D43,MATCH(B7,'客户汇总'!A4:A43,0)) | E7: =C7/SUM('客户汇总'!B4:B43) | F7: =F6+E7
A8: 5 | B8: =INDEX('客户汇总'!A4:A43,MATCH(LARGE('客户汇总'!B4:B43,A8),'客户汇总'!B4:B43,0)) | C8: =LARGE('客户汇总'!B4:B43,A8) | D8: =INDEX('客户汇总'!D4:D43,MATCH(B8,'客户汇总'!A4:A43,0)) | E8: =C8/SUM('客户汇总'!B4:B43) | F8: =F7+E8
A9: 6 | B9: =INDEX('客户汇总'!A4:A43,MATCH(LARGE('客户汇总'!B4:B43,A9),'客户汇总'!B4:B43,0)) | C9: =LARGE('客户汇总'!B4:B43,A9) | D9: =INDEX('客户汇总'!D4:D43,MATCH(B9,'客户汇总'!A4:A43,0)) | E9: =C9/SUM('客户汇总'!B4:B43) | F9: =F8+E9
A10: 7 | B10: =INDEX('客户汇总'!A4:A43,MATCH(LARGE('客户汇总'!B4:B43,A10),'客户汇总'!B4:B43,0)) | C10: =LARGE('客户汇总'!B4:B43,A10) | D10: =INDEX('客户汇总'!D4:D43,MATCH(B10,'客户汇总'!A4:A43,0)) | E10: =C10/SUM('客户汇总'!B4:B43) | F10: =F9+E10
A11: 8 | B11: =INDEX('客户汇总'!A4:A43,MATCH(LARGE('客户汇总'!B4:B43,A11),'客户汇总'!B4:B43,0)) | C11: =LARGE('客户汇总'!B4:B43,A11) | D11: =INDEX('客户汇总'!D4:D43,MATCH(B11,'客户汇总'!A4:A43,0)) | E11: =C11/SUM('客户汇总'!B4:B43) | F11: =F10+E11
A12: 9 | B12: =INDEX('客户汇总'!A4:A43,MATCH(LARGE('客户汇总'!B4:B43,A12),'客户汇总'!B4:B43,0)) | C12: =LARGE('客户汇总'!B4:B43,A12) | D12: =INDEX('客户汇总'!D4:D43,MATCH(B12,'客户汇总'!A4:A43,0)) | E12: =C12/SUM('客户汇总'!B4:B43) | F12: =F11+E12
A13: 10 | B13: =INDEX('客户汇总'!A4:A43,MATCH(LARGE('客户汇总'!B4:B43,A13),'客户汇总'!B4:B43,0)) | C13: =LARGE('客户汇总'!B4:B43,A13) | D13: =INDEX('客户汇总'!D4:D43,MATCH(B13,'客户汇总'!A4:A43,0)) | E13: =C13/SUM('客户汇总'!B4:B43) | F13: =F12+E13
B15: 合计 | C15: =SUM(C4:C13) | E15: =SUM(E4:E13)

Sheet KPI仪表盘
A1: KPI 达成率仪表盘
A2: 达成率 = 实际值 / 目标值；数据条直观展示完成进度
A4: KPI 指标 | B4: 目标 | C4: 实际 | D4: 达成率 | E4: 状态
A5: 年销售额(元) | B5: 72000000 | C5: =SUM('销售明细'!F2:F1201) | D5: =IF(C5=0,"",C5/B5) | E5: =IF(D5="","",IF(D5>=1,"达标",IF(D5>=0.8,"接近","未达标")))
A6: 年毛利(元) | B6: 25000000 | C6: =SUM('销售明细'!F2:F1201)-SUM('销售明细'!G2:G1201) | D6: =IF(C6=0,"",C6/B6) | E6: =IF(D6="","",IF(D6>=1,"达标",IF(D6>=0.8,"接近","未达标")))
A7: 平均毛利率 | B7: 0.33 | C7: =IF(SUM('销售明细'!F2:F1201)=0,"",(SUM('销售明细'!F2:F1201)-SUM('销售明细'!G2:G1201))/SUM('销售明细'!F2:F1201)) | D7: =IF(C7=0,"",C7/B7) | E7: =IF(D7="","",IF(D7>=1,"达标",IF(D7>=0.8,"接近","未达标")))
A8: Top10客户贡献占比 | B8: 0.3 | C8: =SUM('Top10客户'!E4:E13) | D8: =IF(C8=0,"",C8/B8) | E8: =IF(D8="","",IF(D8>=1,"达标",IF(D8>=0.8,"接近","未达标")))
A9: 活跃销售员数 | B9: 5 | C9: =SUMPRODUCT(1/COUNTIF('销售明细'!D2:D1201,'销售明细'!D2:D1201)) | D9: =IF(C9=0,"",C9/B9) | E9: =IF(D9="","",IF(D9>=1,"达标",IF(D9>=0.8,"接近","未达标")))
